ERROR - 2025-04-23 02:51:41 --> Exception: Unable to prepare statement: 1, no such table: db_users in C:\xampp\htdocs\DevOps\system\Database\SQLite3\Connection.php:176
Stack trace:
#0 C:\xampp\htdocs\DevOps\system\Database\SQLite3\Connection.php(176): SQLite3->query('SELECT *\nFROM `...')
#1 C:\xampp\htdocs\DevOps\system\Database\BaseConnection.php(738): CodeIgniter\Database\SQLite3\Connection->execute('SELECT *\nFROM `...')
#2 C:\xampp\htdocs\DevOps\system\Database\BaseConnection.php(652): CodeIgniter\Database\BaseConnection->simpleQuery('SELECT *\nFROM `...')
#3 C:\xampp\htdocs\DevOps\system\Database\BaseBuilder.php(1649): CodeIgniter\Database\BaseConnection->query('SELECT *\nFROM `...', Array, false)
#4 C:\xampp\htdocs\DevOps\system\Model.php(286): CodeIgniter\Database\BaseBuilder->get()
#5 C:\xampp\htdocs\DevOps\system\BaseModel.php(675): CodeIgniter\Model->doFindAll(0, 0)
#6 C:\xampp\htdocs\DevOps\tests\Models\UserModelTest.php(15): CodeIgniter\BaseModel->findAll()
#7 C:\xampp\htdocs\DevOps\vendor\phpunit\phpunit\src\Framework\TestCase.php(1656): App\Tests\Models\UserModelTest->testFindAllUsers()
#8 C:\xampp\htdocs\DevOps\vendor\phpunit\phpunit\src\Framework\TestCase.php(514): PHPUnit\Framework\TestCase->runTest()
#9 C:\xampp\htdocs\DevOps\vendor\phpunit\phpunit\src\Framework\TestRunner\TestRunner.php(87): PHPUnit\Framework\TestCase->runBare()
#10 C:\xampp\htdocs\DevOps\vendor\phpunit\phpunit\src\Framework\TestCase.php(361): PHPUnit\Framework\TestRunner->run(Object(App\Tests\Models\UserModelTest))
#11 C:\xampp\htdocs\DevOps\vendor\phpunit\phpunit\src\Framework\TestSuite.php(369): PHPUnit\Framework\TestCase->run()
#12 C:\xampp\htdocs\DevOps\vendor\phpunit\phpunit\src\Framework\TestSuite.php(369): PHPUnit\Framework\TestSuite->run()
#13 C:\xampp\htdocs\DevOps\vendor\phpunit\phpunit\src\Framework\TestSuite.php(369): PHPUnit\Framework\TestSuite->run()
#14 C:\xampp\htdocs\DevOps\vendor\phpunit\phpunit\src\TextUI\TestRunner.php(64): PHPUnit\Framework\TestSuite->run()
#15 C:\xampp\htdocs\DevOps\vendor\phpunit\phpunit\src\TextUI\Application.php(210): PHPUnit\TextUI\TestRunner->run(Object(PHPUnit\TextUI\Configuration\Configuration), Object(PHPUnit\Runner\ResultCache\DefaultResultCache), Object(PHPUnit\Framework\TestSuite))
#16 C:\xampp\htdocs\DevOps\vendor\phpunit\phpunit\phpunit(104): PHPUnit\TextUI\Application->run(Array)
#17 C:\xampp\htdocs\DevOps\vendor\bin\phpunit(122): include('C:\\xampp\\htdocs...')
#18 {main}
ERROR - 2025-04-23 02:51:41 --> Exception: no such table: db_users in C:\xampp\htdocs\DevOps\system\Database\SQLite3\Connection.php:175
Stack trace:
#0 C:\xampp\htdocs\DevOps\system\Database\SQLite3\Connection.php(175): SQLite3->exec('INSERT INTO `db...')
#1 C:\xampp\htdocs\DevOps\system\Database\BaseConnection.php(738): CodeIgniter\Database\SQLite3\Connection->execute('INSERT INTO `db...')
#2 C:\xampp\htdocs\DevOps\system\Database\BaseConnection.php(652): CodeIgniter\Database\BaseConnection->simpleQuery('INSERT INTO `db...')
#3 C:\xampp\htdocs\DevOps\system\Database\BaseBuilder.php(2345): CodeIgniter\Database\BaseConnection->query('INSERT INTO `db...', Array, false)
#4 C:\xampp\htdocs\DevOps\system\Model.php(394): CodeIgniter\Database\BaseBuilder->insert()
#5 C:\xampp\htdocs\DevOps\system\BaseModel.php(839): CodeIgniter\Model->doInsert(Array)
#6 C:\xampp\htdocs\DevOps\system\Model.php(800): CodeIgniter\BaseModel->insert(Array, true)
#7 C:\xampp\htdocs\DevOps\tests\Models\UserModelTest.php(26): CodeIgniter\Model->insert(Array)
#8 C:\xampp\htdocs\DevOps\vendor\phpunit\phpunit\src\Framework\TestCase.php(1656): App\Tests\Models\UserModelTest->testInsertUser()
#9 C:\xampp\htdocs\DevOps\vendor\phpunit\phpunit\src\Framework\TestCase.php(514): PHPUnit\Framework\TestCase->runTest()
#10 C:\xampp\htdocs\DevOps\vendor\phpunit\phpunit\src\Framework\TestRunner\TestRunner.php(87): PHPUnit\Framework\TestCase->runBare()
#11 C:\xampp\htdocs\DevOps\vendor\phpunit\phpunit\src\Framework\TestCase.php(361): PHPUnit\Framework\TestRunner->run(Object(App\Tests\Models\UserModelTest))
#12 C:\xampp\htdocs\DevOps\vendor\phpunit\phpunit\src\Framework\TestSuite.php(369): PHPUnit\Framework\TestCase->run()
#13 C:\xampp\htdocs\DevOps\vendor\phpunit\phpunit\src\Framework\TestSuite.php(369): PHPUnit\Framework\TestSuite->run()
#14 C:\xampp\htdocs\DevOps\vendor\phpunit\phpunit\src\Framework\TestSuite.php(369): PHPUnit\Framework\TestSuite->run()
#15 C:\xampp\htdocs\DevOps\vendor\phpunit\phpunit\src\TextUI\TestRunner.php(64): PHPUnit\Framework\TestSuite->run()
#16 C:\xampp\htdocs\DevOps\vendor\phpunit\phpunit\src\TextUI\Application.php(210): PHPUnit\TextUI\TestRunner->run(Object(PHPUnit\TextUI\Configuration\Configuration), Object(PHPUnit\Runner\ResultCache\DefaultResultCache), Object(PHPUnit\Framework\TestSuite))
#17 C:\xampp\htdocs\DevOps\vendor\phpunit\phpunit\phpunit(104): PHPUnit\TextUI\Application->run(Array)
#18 C:\xampp\htdocs\DevOps\vendor\bin\phpunit(122): include('C:\\xampp\\htdocs...')
#19 {main}
ERROR - 2025-04-23 02:57:09 --> Exception: Unable to prepare statement: 1, no such table: db_users in C:\xampp\htdocs\DevOps\system\Database\SQLite3\Connection.php:176
Stack trace:
#0 C:\xampp\htdocs\DevOps\system\Database\SQLite3\Connection.php(176): SQLite3->query('SELECT *\nFROM `...')
#1 C:\xampp\htdocs\DevOps\system\Database\BaseConnection.php(738): CodeIgniter\Database\SQLite3\Connection->execute('SELECT *\nFROM `...')
#2 C:\xampp\htdocs\DevOps\system\Database\BaseConnection.php(652): CodeIgniter\Database\BaseConnection->simpleQuery('SELECT *\nFROM `...')
#3 C:\xampp\htdocs\DevOps\system\Database\BaseBuilder.php(1649): CodeIgniter\Database\BaseConnection->query('SELECT *\nFROM `...', Array, false)
#4 C:\xampp\htdocs\DevOps\system\Model.php(286): CodeIgniter\Database\BaseBuilder->get()
#5 C:\xampp\htdocs\DevOps\system\BaseModel.php(675): CodeIgniter\Model->doFindAll(0, 0)
#6 C:\xampp\htdocs\DevOps\tests\Models\UserModelTest.php(15): CodeIgniter\BaseModel->findAll()
#7 C:\xampp\htdocs\DevOps\vendor\phpunit\phpunit\src\Framework\TestCase.php(1656): App\Tests\Models\UserModelTest->testFindAllUsers()
#8 C:\xampp\htdocs\DevOps\vendor\phpunit\phpunit\src\Framework\TestCase.php(514): PHPUnit\Framework\TestCase->runTest()
#9 C:\xampp\htdocs\DevOps\vendor\phpunit\phpunit\src\Framework\TestRunner\TestRunner.php(87): PHPUnit\Framework\TestCase->runBare()
#10 C:\xampp\htdocs\DevOps\vendor\phpunit\phpunit\src\Framework\TestCase.php(361): PHPUnit\Framework\TestRunner->run(Object(App\Tests\Models\UserModelTest))
#11 C:\xampp\htdocs\DevOps\vendor\phpunit\phpunit\src\Framework\TestSuite.php(369): PHPUnit\Framework\TestCase->run()
#12 C:\xampp\htdocs\DevOps\vendor\phpunit\phpunit\src\TextUI\TestRunner.php(64): PHPUnit\Framework\TestSuite->run()
#13 C:\xampp\htdocs\DevOps\vendor\phpunit\phpunit\src\TextUI\Application.php(210): PHPUnit\TextUI\TestRunner->run(Object(PHPUnit\TextUI\Configuration\Configuration), Object(PHPUnit\Runner\ResultCache\DefaultResultCache), Object(PHPUnit\Framework\TestSuite))
#14 C:\xampp\htdocs\DevOps\vendor\phpunit\phpunit\phpunit(104): PHPUnit\TextUI\Application->run(Array)
#15 C:\xampp\htdocs\DevOps\vendor\bin\phpunit(122): include('C:\\xampp\\htdocs...')
#16 {main}
ERROR - 2025-04-23 02:57:09 --> Exception: no such table: db_users in C:\xampp\htdocs\DevOps\system\Database\SQLite3\Connection.php:175
Stack trace:
#0 C:\xampp\htdocs\DevOps\system\Database\SQLite3\Connection.php(175): SQLite3->exec('INSERT INTO `db...')
#1 C:\xampp\htdocs\DevOps\system\Database\BaseConnection.php(738): CodeIgniter\Database\SQLite3\Connection->execute('INSERT INTO `db...')
#2 C:\xampp\htdocs\DevOps\system\Database\BaseConnection.php(652): CodeIgniter\Database\BaseConnection->simpleQuery('INSERT INTO `db...')
#3 C:\xampp\htdocs\DevOps\system\Database\BaseBuilder.php(2345): CodeIgniter\Database\BaseConnection->query('INSERT INTO `db...', Array, false)
#4 C:\xampp\htdocs\DevOps\system\Model.php(394): CodeIgniter\Database\BaseBuilder->insert()
#5 C:\xampp\htdocs\DevOps\system\BaseModel.php(839): CodeIgniter\Model->doInsert(Array)
#6 C:\xampp\htdocs\DevOps\system\Model.php(800): CodeIgniter\BaseModel->insert(Array, true)
#7 C:\xampp\htdocs\DevOps\tests\Models\UserModelTest.php(26): CodeIgniter\Model->insert(Array)
#8 C:\xampp\htdocs\DevOps\vendor\phpunit\phpunit\src\Framework\TestCase.php(1656): App\Tests\Models\UserModelTest->testInsertUser()
#9 C:\xampp\htdocs\DevOps\vendor\phpunit\phpunit\src\Framework\TestCase.php(514): PHPUnit\Framework\TestCase->runTest()
#10 C:\xampp\htdocs\DevOps\vendor\phpunit\phpunit\src\Framework\TestRunner\TestRunner.php(87): PHPUnit\Framework\TestCase->runBare()
#11 C:\xampp\htdocs\DevOps\vendor\phpunit\phpunit\src\Framework\TestCase.php(361): PHPUnit\Framework\TestRunner->run(Object(App\Tests\Models\UserModelTest))
#12 C:\xampp\htdocs\DevOps\vendor\phpunit\phpunit\src\Framework\TestSuite.php(369): PHPUnit\Framework\TestCase->run()
#13 C:\xampp\htdocs\DevOps\vendor\phpunit\phpunit\src\TextUI\TestRunner.php(64): PHPUnit\Framework\TestSuite->run()
#14 C:\xampp\htdocs\DevOps\vendor\phpunit\phpunit\src\TextUI\Application.php(210): PHPUnit\TextUI\TestRunner->run(Object(PHPUnit\TextUI\Configuration\Configuration), Object(PHPUnit\Runner\ResultCache\DefaultResultCache), Object(PHPUnit\Framework\TestSuite))
#15 C:\xampp\htdocs\DevOps\vendor\phpunit\phpunit\phpunit(104): PHPUnit\TextUI\Application->run(Array)
#16 C:\xampp\htdocs\DevOps\vendor\bin\phpunit(122): include('C:\\xampp\\htdocs...')
#17 {main}
ERROR - 2025-04-23 01:00:51 --> Error connecting to the database: mysqli_sql_exception: Access denied for user ''@'localhost' (using password: NO) in C:\xampp\htdocs\DevOps\system\Database\MySQLi\Connection.php:201
Stack trace:
#0 C:\xampp\htdocs\DevOps\system\Database\MySQLi\Connection.php(201): mysqli->real_connect('localhost', '', Object(SensitiveParameterValue), '', 3306, '', 0)
#1 C:\xampp\htdocs\DevOps\system\Database\BaseConnection.php(421): CodeIgniter\Database\MySQLi\Connection->connect(false)
#2 C:\xampp\htdocs\DevOps\system\Database\BaseConnection.php(620): CodeIgniter\Database\BaseConnection->initialize()
#3 C:\xampp\htdocs\DevOps\system\Database\BaseConnection.php(1525): CodeIgniter\Database\BaseConnection->query('SHOW TABLES FRO...')
#4 C:\xampp\htdocs\DevOps\system\Database\BaseConnection.php(1545): CodeIgniter\Database\BaseConnection->listTables()
#5 C:\xampp\htdocs\DevOps\system\Database\MigrationRunner.php(758): CodeIgniter\Database\BaseConnection->tableExists('migrations')
#6 C:\xampp\htdocs\DevOps\system\Database\MigrationRunner.php(162): CodeIgniter\Database\MigrationRunner->ensureTable()
#7 C:\xampp\htdocs\DevOps\system\Commands\Database\Migrate.php(85): CodeIgniter\Database\MigrationRunner->latest(NULL)
#8 C:\xampp\htdocs\DevOps\system\CLI\Commands.php(70): CodeIgniter\Commands\Database\Migrate->run(Array)
#9 C:\xampp\htdocs\DevOps\system\CLI\Console.php(48): CodeIgniter\CLI\Commands->run('migrate', Array)
#10 C:\xampp\htdocs\DevOps\system\Boot.php(360): CodeIgniter\CLI\Console->run()
#11 C:\xampp\htdocs\DevOps\system\Boot.php(104): CodeIgniter\Boot::runCommand(Object(CodeIgniter\CLI\Console))
#12 C:\xampp\htdocs\DevOps\spark(84): CodeIgniter\Boot::bootSpark(Object(Config\Paths))
#13 {main}

Next CodeIgniter\Database\Exceptions\DatabaseException: Access denied for user ''@'localhost' (using password: NO) in C:\xampp\htdocs\DevOps\system\Database\MySQLi\Connection.php:246
Stack trace:
#0 C:\xampp\htdocs\DevOps\system\Database\BaseConnection.php(421): CodeIgniter\Database\MySQLi\Connection->connect(false)
#1 C:\xampp\htdocs\DevOps\system\Database\BaseConnection.php(620): CodeIgniter\Database\BaseConnection->initialize()
#2 C:\xampp\htdocs\DevOps\system\Database\BaseConnection.php(1525): CodeIgniter\Database\BaseConnection->query('SHOW TABLES FRO...')
#3 C:\xampp\htdocs\DevOps\system\Database\BaseConnection.php(1545): CodeIgniter\Database\BaseConnection->listTables()
#4 C:\xampp\htdocs\DevOps\system\Database\MigrationRunner.php(758): CodeIgniter\Database\BaseConnection->tableExists('migrations')
#5 C:\xampp\htdocs\DevOps\system\Database\MigrationRunner.php(162): CodeIgniter\Database\MigrationRunner->ensureTable()
#6 C:\xampp\htdocs\DevOps\system\Commands\Database\Migrate.php(85): CodeIgniter\Database\MigrationRunner->latest(NULL)
#7 C:\xampp\htdocs\DevOps\system\CLI\Commands.php(70): CodeIgniter\Commands\Database\Migrate->run(Array)
#8 C:\xampp\htdocs\DevOps\system\CLI\Console.php(48): CodeIgniter\CLI\Commands->run('migrate', Array)
#9 C:\xampp\htdocs\DevOps\system\Boot.php(360): CodeIgniter\CLI\Console->run()
#10 C:\xampp\htdocs\DevOps\system\Boot.php(104): CodeIgniter\Boot::runCommand(Object(CodeIgniter\CLI\Console))
#11 C:\xampp\htdocs\DevOps\spark(84): CodeIgniter\Boot::bootSpark(Object(Config\Paths))
#12 {main}
ERROR - 2025-04-23 01:08:40 --> Error connecting to the database: mysqli_sql_exception: Access denied for user ''@'localhost' (using password: NO) in C:\xampp\htdocs\DevOps\system\Database\MySQLi\Connection.php:201
Stack trace:
#0 C:\xampp\htdocs\DevOps\system\Database\MySQLi\Connection.php(201): mysqli->real_connect('localhost', '', Object(SensitiveParameterValue), '', 3306, '', 0)
#1 C:\xampp\htdocs\DevOps\system\Database\BaseConnection.php(421): CodeIgniter\Database\MySQLi\Connection->connect(false)
#2 C:\xampp\htdocs\DevOps\system\Database\BaseConnection.php(620): CodeIgniter\Database\BaseConnection->initialize()
#3 C:\xampp\htdocs\DevOps\system\Database\BaseConnection.php(1525): CodeIgniter\Database\BaseConnection->query('SHOW TABLES FRO...')
#4 C:\xampp\htdocs\DevOps\system\Database\BaseConnection.php(1545): CodeIgniter\Database\BaseConnection->listTables()
#5 C:\xampp\htdocs\DevOps\system\Database\MigrationRunner.php(758): CodeIgniter\Database\BaseConnection->tableExists('migrations')
#6 C:\xampp\htdocs\DevOps\system\Database\MigrationRunner.php(162): CodeIgniter\Database\MigrationRunner->ensureTable()
#7 C:\xampp\htdocs\DevOps\system\Commands\Database\Migrate.php(85): CodeIgniter\Database\MigrationRunner->latest(NULL)
#8 C:\xampp\htdocs\DevOps\system\CLI\Commands.php(70): CodeIgniter\Commands\Database\Migrate->run(Array)
#9 C:\xampp\htdocs\DevOps\system\CLI\Console.php(48): CodeIgniter\CLI\Commands->run('migrate', Array)
#10 C:\xampp\htdocs\DevOps\system\Boot.php(360): CodeIgniter\CLI\Console->run()
#11 C:\xampp\htdocs\DevOps\system\Boot.php(104): CodeIgniter\Boot::runCommand(Object(CodeIgniter\CLI\Console))
#12 C:\xampp\htdocs\DevOps\spark(84): CodeIgniter\Boot::bootSpark(Object(Config\Paths))
#13 {main}

Next CodeIgniter\Database\Exceptions\DatabaseException: Access denied for user ''@'localhost' (using password: NO) in C:\xampp\htdocs\DevOps\system\Database\MySQLi\Connection.php:246
Stack trace:
#0 C:\xampp\htdocs\DevOps\system\Database\BaseConnection.php(421): CodeIgniter\Database\MySQLi\Connection->connect(false)
#1 C:\xampp\htdocs\DevOps\system\Database\BaseConnection.php(620): CodeIgniter\Database\BaseConnection->initialize()
#2 C:\xampp\htdocs\DevOps\system\Database\BaseConnection.php(1525): CodeIgniter\Database\BaseConnection->query('SHOW TABLES FRO...')
#3 C:\xampp\htdocs\DevOps\system\Database\BaseConnection.php(1545): CodeIgniter\Database\BaseConnection->listTables()
#4 C:\xampp\htdocs\DevOps\system\Database\MigrationRunner.php(758): CodeIgniter\Database\BaseConnection->tableExists('migrations')
#5 C:\xampp\htdocs\DevOps\system\Database\MigrationRunner.php(162): CodeIgniter\Database\MigrationRunner->ensureTable()
#6 C:\xampp\htdocs\DevOps\system\Commands\Database\Migrate.php(85): CodeIgniter\Database\MigrationRunner->latest(NULL)
#7 C:\xampp\htdocs\DevOps\system\CLI\Commands.php(70): CodeIgniter\Commands\Database\Migrate->run(Array)
#8 C:\xampp\htdocs\DevOps\system\CLI\Console.php(48): CodeIgniter\CLI\Commands->run('migrate', Array)
#9 C:\xampp\htdocs\DevOps\system\Boot.php(360): CodeIgniter\CLI\Console->run()
#10 C:\xampp\htdocs\DevOps\system\Boot.php(104): CodeIgniter\Boot::runCommand(Object(CodeIgniter\CLI\Console))
#11 C:\xampp\htdocs\DevOps\spark(84): CodeIgniter\Boot::bootSpark(Object(Config\Paths))
#12 {main}
ERROR - 2025-04-23 03:11:14 --> Exception: Unable to prepare statement: 1, no such table: db_users in C:\xampp\htdocs\DevOps\system\Database\SQLite3\Connection.php:176
Stack trace:
#0 C:\xampp\htdocs\DevOps\system\Database\SQLite3\Connection.php(176): SQLite3->query('SELECT *\nFROM `...')
#1 C:\xampp\htdocs\DevOps\system\Database\BaseConnection.php(738): CodeIgniter\Database\SQLite3\Connection->execute('SELECT *\nFROM `...')
#2 C:\xampp\htdocs\DevOps\system\Database\BaseConnection.php(652): CodeIgniter\Database\BaseConnection->simpleQuery('SELECT *\nFROM `...')
#3 C:\xampp\htdocs\DevOps\system\Database\BaseBuilder.php(1649): CodeIgniter\Database\BaseConnection->query('SELECT *\nFROM `...', Array, false)
#4 C:\xampp\htdocs\DevOps\system\Model.php(286): CodeIgniter\Database\BaseBuilder->get()
#5 C:\xampp\htdocs\DevOps\system\BaseModel.php(675): CodeIgniter\Model->doFindAll(0, 0)
#6 C:\xampp\htdocs\DevOps\tests\Models\UserModelTest.php(15): CodeIgniter\BaseModel->findAll()
#7 C:\xampp\htdocs\DevOps\vendor\phpunit\phpunit\src\Framework\TestCase.php(1656): App\Tests\Models\UserModelTest->testFindAllUsers()
#8 C:\xampp\htdocs\DevOps\vendor\phpunit\phpunit\src\Framework\TestCase.php(514): PHPUnit\Framework\TestCase->runTest()
#9 C:\xampp\htdocs\DevOps\vendor\phpunit\phpunit\src\Framework\TestRunner\TestRunner.php(87): PHPUnit\Framework\TestCase->runBare()
#10 C:\xampp\htdocs\DevOps\vendor\phpunit\phpunit\src\Framework\TestCase.php(361): PHPUnit\Framework\TestRunner->run(Object(App\Tests\Models\UserModelTest))
#11 C:\xampp\htdocs\DevOps\vendor\phpunit\phpunit\src\Framework\TestSuite.php(369): PHPUnit\Framework\TestCase->run()
#12 C:\xampp\htdocs\DevOps\vendor\phpunit\phpunit\src\TextUI\TestRunner.php(64): PHPUnit\Framework\TestSuite->run()
#13 C:\xampp\htdocs\DevOps\vendor\phpunit\phpunit\src\TextUI\Application.php(210): PHPUnit\TextUI\TestRunner->run(Object(PHPUnit\TextUI\Configuration\Configuration), Object(PHPUnit\Runner\ResultCache\DefaultResultCache), Object(PHPUnit\Framework\TestSuite))
#14 C:\xampp\htdocs\DevOps\vendor\phpunit\phpunit\phpunit(104): PHPUnit\TextUI\Application->run(Array)
#15 C:\xampp\htdocs\DevOps\vendor\bin\phpunit(122): include('C:\\xampp\\htdocs...')
#16 {main}
ERROR - 2025-04-23 03:11:14 --> Exception: no such table: db_users in C:\xampp\htdocs\DevOps\system\Database\SQLite3\Connection.php:175
Stack trace:
#0 C:\xampp\htdocs\DevOps\system\Database\SQLite3\Connection.php(175): SQLite3->exec('INSERT INTO `db...')
#1 C:\xampp\htdocs\DevOps\system\Database\BaseConnection.php(738): CodeIgniter\Database\SQLite3\Connection->execute('INSERT INTO `db...')
#2 C:\xampp\htdocs\DevOps\system\Database\BaseConnection.php(652): CodeIgniter\Database\BaseConnection->simpleQuery('INSERT INTO `db...')
#3 C:\xampp\htdocs\DevOps\system\Database\BaseBuilder.php(2345): CodeIgniter\Database\BaseConnection->query('INSERT INTO `db...', Array, false)
#4 C:\xampp\htdocs\DevOps\system\Model.php(394): CodeIgniter\Database\BaseBuilder->insert()
#5 C:\xampp\htdocs\DevOps\system\BaseModel.php(839): CodeIgniter\Model->doInsert(Array)
#6 C:\xampp\htdocs\DevOps\system\Model.php(800): CodeIgniter\BaseModel->insert(Array, true)
#7 C:\xampp\htdocs\DevOps\tests\Models\UserModelTest.php(26): CodeIgniter\Model->insert(Array)
#8 C:\xampp\htdocs\DevOps\vendor\phpunit\phpunit\src\Framework\TestCase.php(1656): App\Tests\Models\UserModelTest->testInsertUser()
#9 C:\xampp\htdocs\DevOps\vendor\phpunit\phpunit\src\Framework\TestCase.php(514): PHPUnit\Framework\TestCase->runTest()
#10 C:\xampp\htdocs\DevOps\vendor\phpunit\phpunit\src\Framework\TestRunner\TestRunner.php(87): PHPUnit\Framework\TestCase->runBare()
#11 C:\xampp\htdocs\DevOps\vendor\phpunit\phpunit\src\Framework\TestCase.php(361): PHPUnit\Framework\TestRunner->run(Object(App\Tests\Models\UserModelTest))
#12 C:\xampp\htdocs\DevOps\vendor\phpunit\phpunit\src\Framework\TestSuite.php(369): PHPUnit\Framework\TestCase->run()
#13 C:\xampp\htdocs\DevOps\vendor\phpunit\phpunit\src\TextUI\TestRunner.php(64): PHPUnit\Framework\TestSuite->run()
#14 C:\xampp\htdocs\DevOps\vendor\phpunit\phpunit\src\TextUI\Application.php(210): PHPUnit\TextUI\TestRunner->run(Object(PHPUnit\TextUI\Configuration\Configuration), Object(PHPUnit\Runner\ResultCache\DefaultResultCache), Object(PHPUnit\Framework\TestSuite))
#15 C:\xampp\htdocs\DevOps\vendor\phpunit\phpunit\phpunit(104): PHPUnit\TextUI\Application->run(Array)
#16 C:\xampp\htdocs\DevOps\vendor\bin\phpunit(122): include('C:\\xampp\\htdocs...')
#17 {main}
ERROR - 2025-04-23 03:15:31 --> Exception: Unable to prepare statement: 1, no such table: db_users in C:\xampp\htdocs\DevOps\system\Database\SQLite3\Connection.php:176
Stack trace:
#0 C:\xampp\htdocs\DevOps\system\Database\SQLite3\Connection.php(176): SQLite3->query('SELECT *\nFROM `...')
#1 C:\xampp\htdocs\DevOps\system\Database\BaseConnection.php(738): CodeIgniter\Database\SQLite3\Connection->execute('SELECT *\nFROM `...')
#2 C:\xampp\htdocs\DevOps\system\Database\BaseConnection.php(652): CodeIgniter\Database\BaseConnection->simpleQuery('SELECT *\nFROM `...')
#3 C:\xampp\htdocs\DevOps\system\Database\BaseBuilder.php(1649): CodeIgniter\Database\BaseConnection->query('SELECT *\nFROM `...', Array, false)
#4 C:\xampp\htdocs\DevOps\system\Model.php(286): CodeIgniter\Database\BaseBuilder->get()
#5 C:\xampp\htdocs\DevOps\system\BaseModel.php(675): CodeIgniter\Model->doFindAll(0, 0)
#6 C:\xampp\htdocs\DevOps\tests\Models\UserModelTest.php(15): CodeIgniter\BaseModel->findAll()
#7 C:\xampp\htdocs\DevOps\vendor\phpunit\phpunit\src\Framework\TestCase.php(1656): App\Tests\Models\UserModelTest->testFindAllUsers()
#8 C:\xampp\htdocs\DevOps\vendor\phpunit\phpunit\src\Framework\TestCase.php(514): PHPUnit\Framework\TestCase->runTest()
#9 C:\xampp\htdocs\DevOps\vendor\phpunit\phpunit\src\Framework\TestRunner\TestRunner.php(87): PHPUnit\Framework\TestCase->runBare()
#10 C:\xampp\htdocs\DevOps\vendor\phpunit\phpunit\src\Framework\TestCase.php(361): PHPUnit\Framework\TestRunner->run(Object(App\Tests\Models\UserModelTest))
#11 C:\xampp\htdocs\DevOps\vendor\phpunit\phpunit\src\Framework\TestSuite.php(369): PHPUnit\Framework\TestCase->run()
#12 C:\xampp\htdocs\DevOps\vendor\phpunit\phpunit\src\TextUI\TestRunner.php(64): PHPUnit\Framework\TestSuite->run()
#13 C:\xampp\htdocs\DevOps\vendor\phpunit\phpunit\src\TextUI\Application.php(210): PHPUnit\TextUI\TestRunner->run(Object(PHPUnit\TextUI\Configuration\Configuration), Object(PHPUnit\Runner\ResultCache\DefaultResultCache), Object(PHPUnit\Framework\TestSuite))
#14 C:\xampp\htdocs\DevOps\vendor\phpunit\phpunit\phpunit(104): PHPUnit\TextUI\Application->run(Array)
#15 C:\xampp\htdocs\DevOps\vendor\bin\phpunit(122): include('C:\\xampp\\htdocs...')
#16 {main}
ERROR - 2025-04-23 03:15:31 --> Exception: no such table: db_users in C:\xampp\htdocs\DevOps\system\Database\SQLite3\Connection.php:175
Stack trace:
#0 C:\xampp\htdocs\DevOps\system\Database\SQLite3\Connection.php(175): SQLite3->exec('INSERT INTO `db...')
#1 C:\xampp\htdocs\DevOps\system\Database\BaseConnection.php(738): CodeIgniter\Database\SQLite3\Connection->execute('INSERT INTO `db...')
#2 C:\xampp\htdocs\DevOps\system\Database\BaseConnection.php(652): CodeIgniter\Database\BaseConnection->simpleQuery('INSERT INTO `db...')
#3 C:\xampp\htdocs\DevOps\system\Database\BaseBuilder.php(2345): CodeIgniter\Database\BaseConnection->query('INSERT INTO `db...', Array, false)
#4 C:\xampp\htdocs\DevOps\system\Model.php(394): CodeIgniter\Database\BaseBuilder->insert()
#5 C:\xampp\htdocs\DevOps\system\BaseModel.php(839): CodeIgniter\Model->doInsert(Array)
#6 C:\xampp\htdocs\DevOps\system\Model.php(800): CodeIgniter\BaseModel->insert(Array, true)
#7 C:\xampp\htdocs\DevOps\tests\Models\UserModelTest.php(26): CodeIgniter\Model->insert(Array)
#8 C:\xampp\htdocs\DevOps\vendor\phpunit\phpunit\src\Framework\TestCase.php(1656): App\Tests\Models\UserModelTest->testInsertUser()
#9 C:\xampp\htdocs\DevOps\vendor\phpunit\phpunit\src\Framework\TestCase.php(514): PHPUnit\Framework\TestCase->runTest()
#10 C:\xampp\htdocs\DevOps\vendor\phpunit\phpunit\src\Framework\TestRunner\TestRunner.php(87): PHPUnit\Framework\TestCase->runBare()
#11 C:\xampp\htdocs\DevOps\vendor\phpunit\phpunit\src\Framework\TestCase.php(361): PHPUnit\Framework\TestRunner->run(Object(App\Tests\Models\UserModelTest))
#12 C:\xampp\htdocs\DevOps\vendor\phpunit\phpunit\src\Framework\TestSuite.php(369): PHPUnit\Framework\TestCase->run()
#13 C:\xampp\htdocs\DevOps\vendor\phpunit\phpunit\src\TextUI\TestRunner.php(64): PHPUnit\Framework\TestSuite->run()
#14 C:\xampp\htdocs\DevOps\vendor\phpunit\phpunit\src\TextUI\Application.php(210): PHPUnit\TextUI\TestRunner->run(Object(PHPUnit\TextUI\Configuration\Configuration), Object(PHPUnit\Runner\ResultCache\DefaultResultCache), Object(PHPUnit\Framework\TestSuite))
#15 C:\xampp\htdocs\DevOps\vendor\phpunit\phpunit\phpunit(104): PHPUnit\TextUI\Application->run(Array)
#16 C:\xampp\htdocs\DevOps\vendor\bin\phpunit(122): include('C:\\xampp\\htdocs...')
#17 {main}
ERROR - 2025-04-23 03:19:19 --> Exception: Unable to prepare statement: 1, no such table: db_users in C:\xampp\htdocs\DevOps\system\Database\SQLite3\Connection.php:176
Stack trace:
#0 C:\xampp\htdocs\DevOps\system\Database\SQLite3\Connection.php(176): SQLite3->query('SELECT *\nFROM `...')
#1 C:\xampp\htdocs\DevOps\system\Database\BaseConnection.php(738): CodeIgniter\Database\SQLite3\Connection->execute('SELECT *\nFROM `...')
#2 C:\xampp\htdocs\DevOps\system\Database\BaseConnection.php(652): CodeIgniter\Database\BaseConnection->simpleQuery('SELECT *\nFROM `...')
#3 C:\xampp\htdocs\DevOps\system\Database\BaseBuilder.php(1649): CodeIgniter\Database\BaseConnection->query('SELECT *\nFROM `...', Array, false)
#4 C:\xampp\htdocs\DevOps\system\Model.php(286): CodeIgniter\Database\BaseBuilder->get()
#5 C:\xampp\htdocs\DevOps\system\BaseModel.php(675): CodeIgniter\Model->doFindAll(0, 0)
#6 C:\xampp\htdocs\DevOps\tests\Models\UserModelTest.php(15): CodeIgniter\BaseModel->findAll()
#7 C:\xampp\htdocs\DevOps\vendor\phpunit\phpunit\src\Framework\TestCase.php(1656): App\Tests\Models\UserModelTest->testFindAllUsers()
#8 C:\xampp\htdocs\DevOps\vendor\phpunit\phpunit\src\Framework\TestCase.php(514): PHPUnit\Framework\TestCase->runTest()
#9 C:\xampp\htdocs\DevOps\vendor\phpunit\phpunit\src\Framework\TestRunner\TestRunner.php(87): PHPUnit\Framework\TestCase->runBare()
#10 C:\xampp\htdocs\DevOps\vendor\phpunit\phpunit\src\Framework\TestCase.php(361): PHPUnit\Framework\TestRunner->run(Object(App\Tests\Models\UserModelTest))
#11 C:\xampp\htdocs\DevOps\vendor\phpunit\phpunit\src\Framework\TestSuite.php(369): PHPUnit\Framework\TestCase->run()
#12 C:\xampp\htdocs\DevOps\vendor\phpunit\phpunit\src\TextUI\TestRunner.php(64): PHPUnit\Framework\TestSuite->run()
#13 C:\xampp\htdocs\DevOps\vendor\phpunit\phpunit\src\TextUI\Application.php(210): PHPUnit\TextUI\TestRunner->run(Object(PHPUnit\TextUI\Configuration\Configuration), Object(PHPUnit\Runner\ResultCache\DefaultResultCache), Object(PHPUnit\Framework\TestSuite))
#14 C:\xampp\htdocs\DevOps\vendor\phpunit\phpunit\phpunit(104): PHPUnit\TextUI\Application->run(Array)
#15 C:\xampp\htdocs\DevOps\vendor\bin\phpunit(122): include('C:\\xampp\\htdocs...')
#16 {main}
ERROR - 2025-04-23 03:19:19 --> Exception: no such table: db_users in C:\xampp\htdocs\DevOps\system\Database\SQLite3\Connection.php:175
Stack trace:
#0 C:\xampp\htdocs\DevOps\system\Database\SQLite3\Connection.php(175): SQLite3->exec('INSERT INTO `db...')
#1 C:\xampp\htdocs\DevOps\system\Database\BaseConnection.php(738): CodeIgniter\Database\SQLite3\Connection->execute('INSERT INTO `db...')
#2 C:\xampp\htdocs\DevOps\system\Database\BaseConnection.php(652): CodeIgniter\Database\BaseConnection->simpleQuery('INSERT INTO `db...')
#3 C:\xampp\htdocs\DevOps\system\Database\BaseBuilder.php(2345): CodeIgniter\Database\BaseConnection->query('INSERT INTO `db...', Array, false)
#4 C:\xampp\htdocs\DevOps\system\Model.php(394): CodeIgniter\Database\BaseBuilder->insert()
#5 C:\xampp\htdocs\DevOps\system\BaseModel.php(839): CodeIgniter\Model->doInsert(Array)
#6 C:\xampp\htdocs\DevOps\system\Model.php(800): CodeIgniter\BaseModel->insert(Array, true)
#7 C:\xampp\htdocs\DevOps\tests\Models\UserModelTest.php(26): CodeIgniter\Model->insert(Array)
#8 C:\xampp\htdocs\DevOps\vendor\phpunit\phpunit\src\Framework\TestCase.php(1656): App\Tests\Models\UserModelTest->testInsertUser()
#9 C:\xampp\htdocs\DevOps\vendor\phpunit\phpunit\src\Framework\TestCase.php(514): PHPUnit\Framework\TestCase->runTest()
#10 C:\xampp\htdocs\DevOps\vendor\phpunit\phpunit\src\Framework\TestRunner\TestRunner.php(87): PHPUnit\Framework\TestCase->runBare()
#11 C:\xampp\htdocs\DevOps\vendor\phpunit\phpunit\src\Framework\TestCase.php(361): PHPUnit\Framework\TestRunner->run(Object(App\Tests\Models\UserModelTest))
#12 C:\xampp\htdocs\DevOps\vendor\phpunit\phpunit\src\Framework\TestSuite.php(369): PHPUnit\Framework\TestCase->run()
#13 C:\xampp\htdocs\DevOps\vendor\phpunit\phpunit\src\TextUI\TestRunner.php(64): PHPUnit\Framework\TestSuite->run()
#14 C:\xampp\htdocs\DevOps\vendor\phpunit\phpunit\src\TextUI\Application.php(210): PHPUnit\TextUI\TestRunner->run(Object(PHPUnit\TextUI\Configuration\Configuration), Object(PHPUnit\Runner\ResultCache\DefaultResultCache), Object(PHPUnit\Framework\TestSuite))
#15 C:\xampp\htdocs\DevOps\vendor\phpunit\phpunit\phpunit(104): PHPUnit\TextUI\Application->run(Array)
#16 C:\xampp\htdocs\DevOps\vendor\bin\phpunit(122): include('C:\\xampp\\htdocs...')
#17 {main}
ERROR - 2025-04-23 03:20:27 --> Exception: Unable to prepare statement: 1, no such table: db_users in C:\xampp\htdocs\DevOps\system\Database\SQLite3\Connection.php:176
Stack trace:
#0 C:\xampp\htdocs\DevOps\system\Database\SQLite3\Connection.php(176): SQLite3->query('SELECT *\nFROM `...')
#1 C:\xampp\htdocs\DevOps\system\Database\BaseConnection.php(738): CodeIgniter\Database\SQLite3\Connection->execute('SELECT *\nFROM `...')
#2 C:\xampp\htdocs\DevOps\system\Database\BaseConnection.php(652): CodeIgniter\Database\BaseConnection->simpleQuery('SELECT *\nFROM `...')
#3 C:\xampp\htdocs\DevOps\system\Database\BaseBuilder.php(1649): CodeIgniter\Database\BaseConnection->query('SELECT *\nFROM `...', Array, false)
#4 C:\xampp\htdocs\DevOps\system\Model.php(286): CodeIgniter\Database\BaseBuilder->get()
#5 C:\xampp\htdocs\DevOps\system\BaseModel.php(675): CodeIgniter\Model->doFindAll(0, 0)
#6 C:\xampp\htdocs\DevOps\tests\Models\UserModelTest.php(15): CodeIgniter\BaseModel->findAll()
#7 C:\xampp\htdocs\DevOps\vendor\phpunit\phpunit\src\Framework\TestCase.php(1656): App\Tests\Models\UserModelTest->testFindAllUsers()
#8 C:\xampp\htdocs\DevOps\vendor\phpunit\phpunit\src\Framework\TestCase.php(514): PHPUnit\Framework\TestCase->runTest()
#9 C:\xampp\htdocs\DevOps\vendor\phpunit\phpunit\src\Framework\TestRunner\TestRunner.php(87): PHPUnit\Framework\TestCase->runBare()
#10 C:\xampp\htdocs\DevOps\vendor\phpunit\phpunit\src\Framework\TestCase.php(361): PHPUnit\Framework\TestRunner->run(Object(App\Tests\Models\UserModelTest))
#11 C:\xampp\htdocs\DevOps\vendor\phpunit\phpunit\src\Framework\TestSuite.php(369): PHPUnit\Framework\TestCase->run()
#12 C:\xampp\htdocs\DevOps\vendor\phpunit\phpunit\src\TextUI\TestRunner.php(64): PHPUnit\Framework\TestSuite->run()
#13 C:\xampp\htdocs\DevOps\vendor\phpunit\phpunit\src\TextUI\Application.php(210): PHPUnit\TextUI\TestRunner->run(Object(PHPUnit\TextUI\Configuration\Configuration), Object(PHPUnit\Runner\ResultCache\DefaultResultCache), Object(PHPUnit\Framework\TestSuite))
#14 C:\xampp\htdocs\DevOps\vendor\phpunit\phpunit\phpunit(104): PHPUnit\TextUI\Application->run(Array)
#15 C:\xampp\htdocs\DevOps\vendor\bin\phpunit(122): include('C:\\xampp\\htdocs...')
#16 {main}
ERROR - 2025-04-23 03:20:27 --> Exception: no such table: db_users in C:\xampp\htdocs\DevOps\system\Database\SQLite3\Connection.php:175
Stack trace:
#0 C:\xampp\htdocs\DevOps\system\Database\SQLite3\Connection.php(175): SQLite3->exec('INSERT INTO `db...')
#1 C:\xampp\htdocs\DevOps\system\Database\BaseConnection.php(738): CodeIgniter\Database\SQLite3\Connection->execute('INSERT INTO `db...')
#2 C:\xampp\htdocs\DevOps\system\Database\BaseConnection.php(652): CodeIgniter\Database\BaseConnection->simpleQuery('INSERT INTO `db...')
#3 C:\xampp\htdocs\DevOps\system\Database\BaseBuilder.php(2345): CodeIgniter\Database\BaseConnection->query('INSERT INTO `db...', Array, false)
#4 C:\xampp\htdocs\DevOps\system\Model.php(394): CodeIgniter\Database\BaseBuilder->insert()
#5 C:\xampp\htdocs\DevOps\system\BaseModel.php(839): CodeIgniter\Model->doInsert(Array)
#6 C:\xampp\htdocs\DevOps\system\Model.php(800): CodeIgniter\BaseModel->insert(Array, true)
#7 C:\xampp\htdocs\DevOps\tests\Models\UserModelTest.php(26): CodeIgniter\Model->insert(Array)
#8 C:\xampp\htdocs\DevOps\vendor\phpunit\phpunit\src\Framework\TestCase.php(1656): App\Tests\Models\UserModelTest->testInsertUser()
#9 C:\xampp\htdocs\DevOps\vendor\phpunit\phpunit\src\Framework\TestCase.php(514): PHPUnit\Framework\TestCase->runTest()
#10 C:\xampp\htdocs\DevOps\vendor\phpunit\phpunit\src\Framework\TestRunner\TestRunner.php(87): PHPUnit\Framework\TestCase->runBare()
#11 C:\xampp\htdocs\DevOps\vendor\phpunit\phpunit\src\Framework\TestCase.php(361): PHPUnit\Framework\TestRunner->run(Object(App\Tests\Models\UserModelTest))
#12 C:\xampp\htdocs\DevOps\vendor\phpunit\phpunit\src\Framework\TestSuite.php(369): PHPUnit\Framework\TestCase->run()
#13 C:\xampp\htdocs\DevOps\vendor\phpunit\phpunit\src\TextUI\TestRunner.php(64): PHPUnit\Framework\TestSuite->run()
#14 C:\xampp\htdocs\DevOps\vendor\phpunit\phpunit\src\TextUI\Application.php(210): PHPUnit\TextUI\TestRunner->run(Object(PHPUnit\TextUI\Configuration\Configuration), Object(PHPUnit\Runner\ResultCache\DefaultResultCache), Object(PHPUnit\Framework\TestSuite))
#15 C:\xampp\htdocs\DevOps\vendor\phpunit\phpunit\phpunit(104): PHPUnit\TextUI\Application->run(Array)
#16 C:\xampp\htdocs\DevOps\vendor\bin\phpunit(122): include('C:\\xampp\\htdocs...')
#17 {main}
ERROR - 2025-04-23 03:21:34 --> Exception: Unable to prepare statement: 1, no such table: db_users in C:\xampp\htdocs\DevOps\system\Database\SQLite3\Connection.php:176
Stack trace:
#0 C:\xampp\htdocs\DevOps\system\Database\SQLite3\Connection.php(176): SQLite3->query('SELECT *\nFROM `...')
#1 C:\xampp\htdocs\DevOps\system\Database\BaseConnection.php(738): CodeIgniter\Database\SQLite3\Connection->execute('SELECT *\nFROM `...')
#2 C:\xampp\htdocs\DevOps\system\Database\BaseConnection.php(652): CodeIgniter\Database\BaseConnection->simpleQuery('SELECT *\nFROM `...')
#3 C:\xampp\htdocs\DevOps\system\Database\BaseBuilder.php(1649): CodeIgniter\Database\BaseConnection->query('SELECT *\nFROM `...', Array, false)
#4 C:\xampp\htdocs\DevOps\system\Model.php(286): CodeIgniter\Database\BaseBuilder->get()
#5 C:\xampp\htdocs\DevOps\system\BaseModel.php(675): CodeIgniter\Model->doFindAll(0, 0)
#6 C:\xampp\htdocs\DevOps\tests\Models\UserModelTest.php(15): CodeIgniter\BaseModel->findAll()
#7 C:\xampp\htdocs\DevOps\vendor\phpunit\phpunit\src\Framework\TestCase.php(1656): App\Tests\Models\UserModelTest->testFindAllUsers()
#8 C:\xampp\htdocs\DevOps\vendor\phpunit\phpunit\src\Framework\TestCase.php(514): PHPUnit\Framework\TestCase->runTest()
#9 C:\xampp\htdocs\DevOps\vendor\phpunit\phpunit\src\Framework\TestRunner\TestRunner.php(87): PHPUnit\Framework\TestCase->runBare()
#10 C:\xampp\htdocs\DevOps\vendor\phpunit\phpunit\src\Framework\TestCase.php(361): PHPUnit\Framework\TestRunner->run(Object(App\Tests\Models\UserModelTest))
#11 C:\xampp\htdocs\DevOps\vendor\phpunit\phpunit\src\Framework\TestSuite.php(369): PHPUnit\Framework\TestCase->run()
#12 C:\xampp\htdocs\DevOps\vendor\phpunit\phpunit\src\TextUI\TestRunner.php(64): PHPUnit\Framework\TestSuite->run()
#13 C:\xampp\htdocs\DevOps\vendor\phpunit\phpunit\src\TextUI\Application.php(210): PHPUnit\TextUI\TestRunner->run(Object(PHPUnit\TextUI\Configuration\Configuration), Object(PHPUnit\Runner\ResultCache\DefaultResultCache), Object(PHPUnit\Framework\TestSuite))
#14 C:\xampp\htdocs\DevOps\vendor\phpunit\phpunit\phpunit(104): PHPUnit\TextUI\Application->run(Array)
#15 C:\xampp\htdocs\DevOps\vendor\bin\phpunit(122): include('C:\\xampp\\htdocs...')
#16 {main}
ERROR - 2025-04-23 03:21:34 --> Exception: no such table: db_users in C:\xampp\htdocs\DevOps\system\Database\SQLite3\Connection.php:175
Stack trace:
#0 C:\xampp\htdocs\DevOps\system\Database\SQLite3\Connection.php(175): SQLite3->exec('INSERT INTO `db...')
#1 C:\xampp\htdocs\DevOps\system\Database\BaseConnection.php(738): CodeIgniter\Database\SQLite3\Connection->execute('INSERT INTO `db...')
#2 C:\xampp\htdocs\DevOps\system\Database\BaseConnection.php(652): CodeIgniter\Database\BaseConnection->simpleQuery('INSERT INTO `db...')
#3 C:\xampp\htdocs\DevOps\system\Database\BaseBuilder.php(2345): CodeIgniter\Database\BaseConnection->query('INSERT INTO `db...', Array, false)
#4 C:\xampp\htdocs\DevOps\system\Model.php(394): CodeIgniter\Database\BaseBuilder->insert()
#5 C:\xampp\htdocs\DevOps\system\BaseModel.php(839): CodeIgniter\Model->doInsert(Array)
#6 C:\xampp\htdocs\DevOps\system\Model.php(800): CodeIgniter\BaseModel->insert(Array, true)
#7 C:\xampp\htdocs\DevOps\tests\Models\UserModelTest.php(26): CodeIgniter\Model->insert(Array)
#8 C:\xampp\htdocs\DevOps\vendor\phpunit\phpunit\src\Framework\TestCase.php(1656): App\Tests\Models\UserModelTest->testInsertUser()
#9 C:\xampp\htdocs\DevOps\vendor\phpunit\phpunit\src\Framework\TestCase.php(514): PHPUnit\Framework\TestCase->runTest()
#10 C:\xampp\htdocs\DevOps\vendor\phpunit\phpunit\src\Framework\TestRunner\TestRunner.php(87): PHPUnit\Framework\TestCase->runBare()
#11 C:\xampp\htdocs\DevOps\vendor\phpunit\phpunit\src\Framework\TestCase.php(361): PHPUnit\Framework\TestRunner->run(Object(App\Tests\Models\UserModelTest))
#12 C:\xampp\htdocs\DevOps\vendor\phpunit\phpunit\src\Framework\TestSuite.php(369): PHPUnit\Framework\TestCase->run()
#13 C:\xampp\htdocs\DevOps\vendor\phpunit\phpunit\src\TextUI\TestRunner.php(64): PHPUnit\Framework\TestSuite->run()
#14 C:\xampp\htdocs\DevOps\vendor\phpunit\phpunit\src\TextUI\Application.php(210): PHPUnit\TextUI\TestRunner->run(Object(PHPUnit\TextUI\Configuration\Configuration), Object(PHPUnit\Runner\ResultCache\DefaultResultCache), Object(PHPUnit\Framework\TestSuite))
#15 C:\xampp\htdocs\DevOps\vendor\phpunit\phpunit\phpunit(104): PHPUnit\TextUI\Application->run(Array)
#16 C:\xampp\htdocs\DevOps\vendor\bin\phpunit(122): include('C:\\xampp\\htdocs...')
#17 {main}
ERROR - 2025-04-23 03:23:10 --> Exception: Unable to prepare statement: 1, no such table: db_users in C:\xampp\htdocs\DevOps\system\Database\SQLite3\Connection.php:176
Stack trace:
#0 C:\xampp\htdocs\DevOps\system\Database\SQLite3\Connection.php(176): SQLite3->query('SELECT *\nFROM `...')
#1 C:\xampp\htdocs\DevOps\system\Database\BaseConnection.php(738): CodeIgniter\Database\SQLite3\Connection->execute('SELECT *\nFROM `...')
#2 C:\xampp\htdocs\DevOps\system\Database\BaseConnection.php(652): CodeIgniter\Database\BaseConnection->simpleQuery('SELECT *\nFROM `...')
#3 C:\xampp\htdocs\DevOps\system\Database\BaseBuilder.php(1649): CodeIgniter\Database\BaseConnection->query('SELECT *\nFROM `...', Array, false)
#4 C:\xampp\htdocs\DevOps\system\Model.php(286): CodeIgniter\Database\BaseBuilder->get()
#5 C:\xampp\htdocs\DevOps\system\BaseModel.php(675): CodeIgniter\Model->doFindAll(0, 0)
#6 C:\xampp\htdocs\DevOps\tests\Models\UserModelTest.php(15): CodeIgniter\BaseModel->findAll()
#7 C:\xampp\htdocs\DevOps\vendor\phpunit\phpunit\src\Framework\TestCase.php(1656): App\Tests\Models\UserModelTest->testFindAllUsers()
#8 C:\xampp\htdocs\DevOps\vendor\phpunit\phpunit\src\Framework\TestCase.php(514): PHPUnit\Framework\TestCase->runTest()
#9 C:\xampp\htdocs\DevOps\vendor\phpunit\phpunit\src\Framework\TestRunner\TestRunner.php(87): PHPUnit\Framework\TestCase->runBare()
#10 C:\xampp\htdocs\DevOps\vendor\phpunit\phpunit\src\Framework\TestCase.php(361): PHPUnit\Framework\TestRunner->run(Object(App\Tests\Models\UserModelTest))
#11 C:\xampp\htdocs\DevOps\vendor\phpunit\phpunit\src\Framework\TestSuite.php(369): PHPUnit\Framework\TestCase->run()
#12 C:\xampp\htdocs\DevOps\vendor\phpunit\phpunit\src\TextUI\TestRunner.php(64): PHPUnit\Framework\TestSuite->run()
#13 C:\xampp\htdocs\DevOps\vendor\phpunit\phpunit\src\TextUI\Application.php(210): PHPUnit\TextUI\TestRunner->run(Object(PHPUnit\TextUI\Configuration\Configuration), Object(PHPUnit\Runner\ResultCache\DefaultResultCache), Object(PHPUnit\Framework\TestSuite))
#14 C:\xampp\htdocs\DevOps\vendor\phpunit\phpunit\phpunit(104): PHPUnit\TextUI\Application->run(Array)
#15 C:\xampp\htdocs\DevOps\vendor\bin\phpunit(122): include('C:\\xampp\\htdocs...')
#16 {main}
ERROR - 2025-04-23 03:23:10 --> Exception: no such table: db_users in C:\xampp\htdocs\DevOps\system\Database\SQLite3\Connection.php:175
Stack trace:
#0 C:\xampp\htdocs\DevOps\system\Database\SQLite3\Connection.php(175): SQLite3->exec('INSERT INTO `db...')
#1 C:\xampp\htdocs\DevOps\system\Database\BaseConnection.php(738): CodeIgniter\Database\SQLite3\Connection->execute('INSERT INTO `db...')
#2 C:\xampp\htdocs\DevOps\system\Database\BaseConnection.php(652): CodeIgniter\Database\BaseConnection->simpleQuery('INSERT INTO `db...')
#3 C:\xampp\htdocs\DevOps\system\Database\BaseBuilder.php(2345): CodeIgniter\Database\BaseConnection->query('INSERT INTO `db...', Array, false)
#4 C:\xampp\htdocs\DevOps\system\Model.php(394): CodeIgniter\Database\BaseBuilder->insert()
#5 C:\xampp\htdocs\DevOps\system\BaseModel.php(839): CodeIgniter\Model->doInsert(Array)
#6 C:\xampp\htdocs\DevOps\system\Model.php(800): CodeIgniter\BaseModel->insert(Array, true)
#7 C:\xampp\htdocs\DevOps\tests\Models\UserModelTest.php(26): CodeIgniter\Model->insert(Array)
#8 C:\xampp\htdocs\DevOps\vendor\phpunit\phpunit\src\Framework\TestCase.php(1656): App\Tests\Models\UserModelTest->testInsertUser()
#9 C:\xampp\htdocs\DevOps\vendor\phpunit\phpunit\src\Framework\TestCase.php(514): PHPUnit\Framework\TestCase->runTest()
#10 C:\xampp\htdocs\DevOps\vendor\phpunit\phpunit\src\Framework\TestRunner\TestRunner.php(87): PHPUnit\Framework\TestCase->runBare()
#11 C:\xampp\htdocs\DevOps\vendor\phpunit\phpunit\src\Framework\TestCase.php(361): PHPUnit\Framework\TestRunner->run(Object(App\Tests\Models\UserModelTest))
#12 C:\xampp\htdocs\DevOps\vendor\phpunit\phpunit\src\Framework\TestSuite.php(369): PHPUnit\Framework\TestCase->run()
#13 C:\xampp\htdocs\DevOps\vendor\phpunit\phpunit\src\TextUI\TestRunner.php(64): PHPUnit\Framework\TestSuite->run()
#14 C:\xampp\htdocs\DevOps\vendor\phpunit\phpunit\src\TextUI\Application.php(210): PHPUnit\TextUI\TestRunner->run(Object(PHPUnit\TextUI\Configuration\Configuration), Object(PHPUnit\Runner\ResultCache\DefaultResultCache), Object(PHPUnit\Framework\TestSuite))
#15 C:\xampp\htdocs\DevOps\vendor\phpunit\phpunit\phpunit(104): PHPUnit\TextUI\Application->run(Array)
#16 C:\xampp\htdocs\DevOps\vendor\bin\phpunit(122): include('C:\\xampp\\htdocs...')
#17 {main}
ERROR - 2025-04-23 03:26:23 --> Exception: Unable to prepare statement: 1, no such table: db_users in C:\xampp\htdocs\DevOps\system\Database\SQLite3\Connection.php:176
Stack trace:
#0 C:\xampp\htdocs\DevOps\system\Database\SQLite3\Connection.php(176): SQLite3->query('SELECT *\nFROM `...')
#1 C:\xampp\htdocs\DevOps\system\Database\BaseConnection.php(738): CodeIgniter\Database\SQLite3\Connection->execute('SELECT *\nFROM `...')
#2 C:\xampp\htdocs\DevOps\system\Database\BaseConnection.php(652): CodeIgniter\Database\BaseConnection->simpleQuery('SELECT *\nFROM `...')
#3 C:\xampp\htdocs\DevOps\system\Database\BaseBuilder.php(1649): CodeIgniter\Database\BaseConnection->query('SELECT *\nFROM `...', Array, false)
#4 C:\xampp\htdocs\DevOps\system\Model.php(286): CodeIgniter\Database\BaseBuilder->get()
#5 C:\xampp\htdocs\DevOps\system\BaseModel.php(675): CodeIgniter\Model->doFindAll(0, 0)
#6 C:\xampp\htdocs\DevOps\tests\Models\UserModelTest.php(15): CodeIgniter\BaseModel->findAll()
#7 C:\xampp\htdocs\DevOps\vendor\phpunit\phpunit\src\Framework\TestCase.php(1656): App\Tests\Models\UserModelTest->testFindAllUsers()
#8 C:\xampp\htdocs\DevOps\vendor\phpunit\phpunit\src\Framework\TestCase.php(514): PHPUnit\Framework\TestCase->runTest()
#9 C:\xampp\htdocs\DevOps\vendor\phpunit\phpunit\src\Framework\TestRunner\TestRunner.php(87): PHPUnit\Framework\TestCase->runBare()
#10 C:\xampp\htdocs\DevOps\vendor\phpunit\phpunit\src\Framework\TestCase.php(361): PHPUnit\Framework\TestRunner->run(Object(App\Tests\Models\UserModelTest))
#11 C:\xampp\htdocs\DevOps\vendor\phpunit\phpunit\src\Framework\TestSuite.php(369): PHPUnit\Framework\TestCase->run()
#12 C:\xampp\htdocs\DevOps\vendor\phpunit\phpunit\src\TextUI\TestRunner.php(64): PHPUnit\Framework\TestSuite->run()
#13 C:\xampp\htdocs\DevOps\vendor\phpunit\phpunit\src\TextUI\Application.php(210): PHPUnit\TextUI\TestRunner->run(Object(PHPUnit\TextUI\Configuration\Configuration), Object(PHPUnit\Runner\ResultCache\DefaultResultCache), Object(PHPUnit\Framework\TestSuite))
#14 C:\xampp\htdocs\DevOps\vendor\phpunit\phpunit\phpunit(104): PHPUnit\TextUI\Application->run(Array)
#15 C:\xampp\htdocs\DevOps\vendor\bin\phpunit(122): include('C:\\xampp\\htdocs...')
#16 {main}
ERROR - 2025-04-23 03:26:24 --> Exception: no such table: db_users in C:\xampp\htdocs\DevOps\system\Database\SQLite3\Connection.php:175
Stack trace:
#0 C:\xampp\htdocs\DevOps\system\Database\SQLite3\Connection.php(175): SQLite3->exec('INSERT INTO `db...')
#1 C:\xampp\htdocs\DevOps\system\Database\BaseConnection.php(738): CodeIgniter\Database\SQLite3\Connection->execute('INSERT INTO `db...')
#2 C:\xampp\htdocs\DevOps\system\Database\BaseConnection.php(652): CodeIgniter\Database\BaseConnection->simpleQuery('INSERT INTO `db...')
#3 C:\xampp\htdocs\DevOps\system\Database\BaseBuilder.php(2345): CodeIgniter\Database\BaseConnection->query('INSERT INTO `db...', Array, false)
#4 C:\xampp\htdocs\DevOps\system\Model.php(394): CodeIgniter\Database\BaseBuilder->insert()
#5 C:\xampp\htdocs\DevOps\system\BaseModel.php(839): CodeIgniter\Model->doInsert(Array)
#6 C:\xampp\htdocs\DevOps\system\Model.php(800): CodeIgniter\BaseModel->insert(Array, true)
#7 C:\xampp\htdocs\DevOps\tests\Models\UserModelTest.php(26): CodeIgniter\Model->insert(Array)
#8 C:\xampp\htdocs\DevOps\vendor\phpunit\phpunit\src\Framework\TestCase.php(1656): App\Tests\Models\UserModelTest->testInsertUser()
#9 C:\xampp\htdocs\DevOps\vendor\phpunit\phpunit\src\Framework\TestCase.php(514): PHPUnit\Framework\TestCase->runTest()
#10 C:\xampp\htdocs\DevOps\vendor\phpunit\phpunit\src\Framework\TestRunner\TestRunner.php(87): PHPUnit\Framework\TestCase->runBare()
#11 C:\xampp\htdocs\DevOps\vendor\phpunit\phpunit\src\Framework\TestCase.php(361): PHPUnit\Framework\TestRunner->run(Object(App\Tests\Models\UserModelTest))
#12 C:\xampp\htdocs\DevOps\vendor\phpunit\phpunit\src\Framework\TestSuite.php(369): PHPUnit\Framework\TestCase->run()
#13 C:\xampp\htdocs\DevOps\vendor\phpunit\phpunit\src\TextUI\TestRunner.php(64): PHPUnit\Framework\TestSuite->run()
#14 C:\xampp\htdocs\DevOps\vendor\phpunit\phpunit\src\TextUI\Application.php(210): PHPUnit\TextUI\TestRunner->run(Object(PHPUnit\TextUI\Configuration\Configuration), Object(PHPUnit\Runner\ResultCache\DefaultResultCache), Object(PHPUnit\Framework\TestSuite))
#15 C:\xampp\htdocs\DevOps\vendor\phpunit\phpunit\phpunit(104): PHPUnit\TextUI\Application->run(Array)
#16 C:\xampp\htdocs\DevOps\vendor\bin\phpunit(122): include('C:\\xampp\\htdocs...')
#17 {main}
ERROR - 2025-04-23 03:27:09 --> Exception: Unable to prepare statement: 1, no such table: db_users in C:\xampp\htdocs\DevOps\system\Database\SQLite3\Connection.php:176
Stack trace:
#0 C:\xampp\htdocs\DevOps\system\Database\SQLite3\Connection.php(176): SQLite3->query('SELECT *\nFROM `...')
#1 C:\xampp\htdocs\DevOps\system\Database\BaseConnection.php(738): CodeIgniter\Database\SQLite3\Connection->execute('SELECT *\nFROM `...')
#2 C:\xampp\htdocs\DevOps\system\Database\BaseConnection.php(652): CodeIgniter\Database\BaseConnection->simpleQuery('SELECT *\nFROM `...')
#3 C:\xampp\htdocs\DevOps\system\Database\BaseBuilder.php(1649): CodeIgniter\Database\BaseConnection->query('SELECT *\nFROM `...', Array, false)
#4 C:\xampp\htdocs\DevOps\system\Model.php(286): CodeIgniter\Database\BaseBuilder->get()
#5 C:\xampp\htdocs\DevOps\system\BaseModel.php(675): CodeIgniter\Model->doFindAll(0, 0)
#6 C:\xampp\htdocs\DevOps\tests\Models\UserModelTest.php(15): CodeIgniter\BaseModel->findAll()
#7 C:\xampp\htdocs\DevOps\vendor\phpunit\phpunit\src\Framework\TestCase.php(1656): App\Tests\Models\UserModelTest->testFindAllUsers()
#8 C:\xampp\htdocs\DevOps\vendor\phpunit\phpunit\src\Framework\TestCase.php(514): PHPUnit\Framework\TestCase->runTest()
#9 C:\xampp\htdocs\DevOps\vendor\phpunit\phpunit\src\Framework\TestRunner\TestRunner.php(87): PHPUnit\Framework\TestCase->runBare()
#10 C:\xampp\htdocs\DevOps\vendor\phpunit\phpunit\src\Framework\TestCase.php(361): PHPUnit\Framework\TestRunner->run(Object(App\Tests\Models\UserModelTest))
#11 C:\xampp\htdocs\DevOps\vendor\phpunit\phpunit\src\Framework\TestSuite.php(369): PHPUnit\Framework\TestCase->run()
#12 C:\xampp\htdocs\DevOps\vendor\phpunit\phpunit\src\TextUI\TestRunner.php(64): PHPUnit\Framework\TestSuite->run()
#13 C:\xampp\htdocs\DevOps\vendor\phpunit\phpunit\src\TextUI\Application.php(210): PHPUnit\TextUI\TestRunner->run(Object(PHPUnit\TextUI\Configuration\Configuration), Object(PHPUnit\Runner\ResultCache\DefaultResultCache), Object(PHPUnit\Framework\TestSuite))
#14 C:\xampp\htdocs\DevOps\vendor\phpunit\phpunit\phpunit(104): PHPUnit\TextUI\Application->run(Array)
#15 C:\xampp\htdocs\DevOps\vendor\bin\phpunit(122): include('C:\\xampp\\htdocs...')
#16 {main}
ERROR - 2025-04-23 03:27:09 --> Exception: no such table: db_users in C:\xampp\htdocs\DevOps\system\Database\SQLite3\Connection.php:175
Stack trace:
#0 C:\xampp\htdocs\DevOps\system\Database\SQLite3\Connection.php(175): SQLite3->exec('INSERT INTO `db...')
#1 C:\xampp\htdocs\DevOps\system\Database\BaseConnection.php(738): CodeIgniter\Database\SQLite3\Connection->execute('INSERT INTO `db...')
#2 C:\xampp\htdocs\DevOps\system\Database\BaseConnection.php(652): CodeIgniter\Database\BaseConnection->simpleQuery('INSERT INTO `db...')
#3 C:\xampp\htdocs\DevOps\system\Database\BaseBuilder.php(2345): CodeIgniter\Database\BaseConnection->query('INSERT INTO `db...', Array, false)
#4 C:\xampp\htdocs\DevOps\system\Model.php(394): CodeIgniter\Database\BaseBuilder->insert()
#5 C:\xampp\htdocs\DevOps\system\BaseModel.php(839): CodeIgniter\Model->doInsert(Array)
#6 C:\xampp\htdocs\DevOps\system\Model.php(800): CodeIgniter\BaseModel->insert(Array, true)
#7 C:\xampp\htdocs\DevOps\tests\Models\UserModelTest.php(26): CodeIgniter\Model->insert(Array)
#8 C:\xampp\htdocs\DevOps\vendor\phpunit\phpunit\src\Framework\TestCase.php(1656): App\Tests\Models\UserModelTest->testInsertUser()
#9 C:\xampp\htdocs\DevOps\vendor\phpunit\phpunit\src\Framework\TestCase.php(514): PHPUnit\Framework\TestCase->runTest()
#10 C:\xampp\htdocs\DevOps\vendor\phpunit\phpunit\src\Framework\TestRunner\TestRunner.php(87): PHPUnit\Framework\TestCase->runBare()
#11 C:\xampp\htdocs\DevOps\vendor\phpunit\phpunit\src\Framework\TestCase.php(361): PHPUnit\Framework\TestRunner->run(Object(App\Tests\Models\UserModelTest))
#12 C:\xampp\htdocs\DevOps\vendor\phpunit\phpunit\src\Framework\TestSuite.php(369): PHPUnit\Framework\TestCase->run()
#13 C:\xampp\htdocs\DevOps\vendor\phpunit\phpunit\src\TextUI\TestRunner.php(64): PHPUnit\Framework\TestSuite->run()
#14 C:\xampp\htdocs\DevOps\vendor\phpunit\phpunit\src\TextUI\Application.php(210): PHPUnit\TextUI\TestRunner->run(Object(PHPUnit\TextUI\Configuration\Configuration), Object(PHPUnit\Runner\ResultCache\DefaultResultCache), Object(PHPUnit\Framework\TestSuite))
#15 C:\xampp\htdocs\DevOps\vendor\phpunit\phpunit\phpunit(104): PHPUnit\TextUI\Application->run(Array)
#16 C:\xampp\htdocs\DevOps\vendor\bin\phpunit(122): include('C:\\xampp\\htdocs...')
#17 {main}
ERROR - 2025-04-23 03:30:24 --> Exception: Unable to prepare statement: 1, no such table: db_users in C:\xampp\htdocs\DevOps\system\Database\SQLite3\Connection.php:176
Stack trace:
#0 C:\xampp\htdocs\DevOps\system\Database\SQLite3\Connection.php(176): SQLite3->query('SELECT *\nFROM `...')
#1 C:\xampp\htdocs\DevOps\system\Database\BaseConnection.php(738): CodeIgniter\Database\SQLite3\Connection->execute('SELECT *\nFROM `...')
#2 C:\xampp\htdocs\DevOps\system\Database\BaseConnection.php(652): CodeIgniter\Database\BaseConnection->simpleQuery('SELECT *\nFROM `...')
#3 C:\xampp\htdocs\DevOps\system\Database\BaseBuilder.php(1649): CodeIgniter\Database\BaseConnection->query('SELECT *\nFROM `...', Array, false)
#4 C:\xampp\htdocs\DevOps\system\Model.php(286): CodeIgniter\Database\BaseBuilder->get()
#5 C:\xampp\htdocs\DevOps\system\BaseModel.php(675): CodeIgniter\Model->doFindAll(0, 0)
#6 C:\xampp\htdocs\DevOps\tests\Models\UserModelTest.php(15): CodeIgniter\BaseModel->findAll()
#7 C:\xampp\htdocs\DevOps\vendor\phpunit\phpunit\src\Framework\TestCase.php(1656): App\Tests\Models\UserModelTest->testFindAllUsers()
#8 C:\xampp\htdocs\DevOps\vendor\phpunit\phpunit\src\Framework\TestCase.php(514): PHPUnit\Framework\TestCase->runTest()
#9 C:\xampp\htdocs\DevOps\vendor\phpunit\phpunit\src\Framework\TestRunner\TestRunner.php(87): PHPUnit\Framework\TestCase->runBare()
#10 C:\xampp\htdocs\DevOps\vendor\phpunit\phpunit\src\Framework\TestCase.php(361): PHPUnit\Framework\TestRunner->run(Object(App\Tests\Models\UserModelTest))
#11 C:\xampp\htdocs\DevOps\vendor\phpunit\phpunit\src\Framework\TestSuite.php(369): PHPUnit\Framework\TestCase->run()
#12 C:\xampp\htdocs\DevOps\vendor\phpunit\phpunit\src\TextUI\TestRunner.php(64): PHPUnit\Framework\TestSuite->run()
#13 C:\xampp\htdocs\DevOps\vendor\phpunit\phpunit\src\TextUI\Application.php(210): PHPUnit\TextUI\TestRunner->run(Object(PHPUnit\TextUI\Configuration\Configuration), Object(PHPUnit\Runner\ResultCache\DefaultResultCache), Object(PHPUnit\Framework\TestSuite))
#14 C:\xampp\htdocs\DevOps\vendor\phpunit\phpunit\phpunit(104): PHPUnit\TextUI\Application->run(Array)
#15 C:\xampp\htdocs\DevOps\vendor\bin\phpunit(122): include('C:\\xampp\\htdocs...')
#16 {main}
ERROR - 2025-04-23 03:30:24 --> Exception: no such table: db_users in C:\xampp\htdocs\DevOps\system\Database\SQLite3\Connection.php:175
Stack trace:
#0 C:\xampp\htdocs\DevOps\system\Database\SQLite3\Connection.php(175): SQLite3->exec('INSERT INTO `db...')
#1 C:\xampp\htdocs\DevOps\system\Database\BaseConnection.php(738): CodeIgniter\Database\SQLite3\Connection->execute('INSERT INTO `db...')
#2 C:\xampp\htdocs\DevOps\system\Database\BaseConnection.php(652): CodeIgniter\Database\BaseConnection->simpleQuery('INSERT INTO `db...')
#3 C:\xampp\htdocs\DevOps\system\Database\BaseBuilder.php(2345): CodeIgniter\Database\BaseConnection->query('INSERT INTO `db...', Array, false)
#4 C:\xampp\htdocs\DevOps\system\Model.php(394): CodeIgniter\Database\BaseBuilder->insert()
#5 C:\xampp\htdocs\DevOps\system\BaseModel.php(839): CodeIgniter\Model->doInsert(Array)
#6 C:\xampp\htdocs\DevOps\system\Model.php(800): CodeIgniter\BaseModel->insert(Array, true)
#7 C:\xampp\htdocs\DevOps\tests\Models\UserModelTest.php(26): CodeIgniter\Model->insert(Array)
#8 C:\xampp\htdocs\DevOps\vendor\phpunit\phpunit\src\Framework\TestCase.php(1656): App\Tests\Models\UserModelTest->testInsertUser()
#9 C:\xampp\htdocs\DevOps\vendor\phpunit\phpunit\src\Framework\TestCase.php(514): PHPUnit\Framework\TestCase->runTest()
#10 C:\xampp\htdocs\DevOps\vendor\phpunit\phpunit\src\Framework\TestRunner\TestRunner.php(87): PHPUnit\Framework\TestCase->runBare()
#11 C:\xampp\htdocs\DevOps\vendor\phpunit\phpunit\src\Framework\TestCase.php(361): PHPUnit\Framework\TestRunner->run(Object(App\Tests\Models\UserModelTest))
#12 C:\xampp\htdocs\DevOps\vendor\phpunit\phpunit\src\Framework\TestSuite.php(369): PHPUnit\Framework\TestCase->run()
#13 C:\xampp\htdocs\DevOps\vendor\phpunit\phpunit\src\TextUI\TestRunner.php(64): PHPUnit\Framework\TestSuite->run()
#14 C:\xampp\htdocs\DevOps\vendor\phpunit\phpunit\src\TextUI\Application.php(210): PHPUnit\TextUI\TestRunner->run(Object(PHPUnit\TextUI\Configuration\Configuration), Object(PHPUnit\Runner\ResultCache\DefaultResultCache), Object(PHPUnit\Framework\TestSuite))
#15 C:\xampp\htdocs\DevOps\vendor\phpunit\phpunit\phpunit(104): PHPUnit\TextUI\Application->run(Array)
#16 C:\xampp\htdocs\DevOps\vendor\bin\phpunit(122): include('C:\\xampp\\htdocs...')
#17 {main}
ERROR - 2025-04-23 03:32:43 --> Exception: Unable to prepare statement: 1, no such table: db_users in C:\xampp\htdocs\DevOps\system\Database\SQLite3\Connection.php:176
Stack trace:
#0 C:\xampp\htdocs\DevOps\system\Database\SQLite3\Connection.php(176): SQLite3->query('SELECT *\nFROM `...')
#1 C:\xampp\htdocs\DevOps\system\Database\BaseConnection.php(738): CodeIgniter\Database\SQLite3\Connection->execute('SELECT *\nFROM `...')
#2 C:\xampp\htdocs\DevOps\system\Database\BaseConnection.php(652): CodeIgniter\Database\BaseConnection->simpleQuery('SELECT *\nFROM `...')
#3 C:\xampp\htdocs\DevOps\system\Database\BaseBuilder.php(1649): CodeIgniter\Database\BaseConnection->query('SELECT *\nFROM `...', Array, false)
#4 C:\xampp\htdocs\DevOps\system\Model.php(286): CodeIgniter\Database\BaseBuilder->get()
#5 C:\xampp\htdocs\DevOps\system\BaseModel.php(675): CodeIgniter\Model->doFindAll(0, 0)
#6 C:\xampp\htdocs\DevOps\tests\Models\UserModelTest.php(15): CodeIgniter\BaseModel->findAll()
#7 C:\xampp\htdocs\DevOps\vendor\phpunit\phpunit\src\Framework\TestCase.php(1656): App\Tests\Models\UserModelTest->testFindAllUsers()
#8 C:\xampp\htdocs\DevOps\vendor\phpunit\phpunit\src\Framework\TestCase.php(514): PHPUnit\Framework\TestCase->runTest()
#9 C:\xampp\htdocs\DevOps\vendor\phpunit\phpunit\src\Framework\TestRunner\TestRunner.php(87): PHPUnit\Framework\TestCase->runBare()
#10 C:\xampp\htdocs\DevOps\vendor\phpunit\phpunit\src\Framework\TestCase.php(361): PHPUnit\Framework\TestRunner->run(Object(App\Tests\Models\UserModelTest))
#11 C:\xampp\htdocs\DevOps\vendor\phpunit\phpunit\src\Framework\TestSuite.php(369): PHPUnit\Framework\TestCase->run()
#12 C:\xampp\htdocs\DevOps\vendor\phpunit\phpunit\src\TextUI\TestRunner.php(64): PHPUnit\Framework\TestSuite->run()
#13 C:\xampp\htdocs\DevOps\vendor\phpunit\phpunit\src\TextUI\Application.php(210): PHPUnit\TextUI\TestRunner->run(Object(PHPUnit\TextUI\Configuration\Configuration), Object(PHPUnit\Runner\ResultCache\DefaultResultCache), Object(PHPUnit\Framework\TestSuite))
#14 C:\xampp\htdocs\DevOps\vendor\phpunit\phpunit\phpunit(104): PHPUnit\TextUI\Application->run(Array)
#15 C:\xampp\htdocs\DevOps\vendor\bin\phpunit(122): include('C:\\xampp\\htdocs...')
#16 {main}
ERROR - 2025-04-23 03:32:44 --> Exception: no such table: db_users in C:\xampp\htdocs\DevOps\system\Database\SQLite3\Connection.php:175
Stack trace:
#0 C:\xampp\htdocs\DevOps\system\Database\SQLite3\Connection.php(175): SQLite3->exec('INSERT INTO `db...')
#1 C:\xampp\htdocs\DevOps\system\Database\BaseConnection.php(738): CodeIgniter\Database\SQLite3\Connection->execute('INSERT INTO `db...')
#2 C:\xampp\htdocs\DevOps\system\Database\BaseConnection.php(652): CodeIgniter\Database\BaseConnection->simpleQuery('INSERT INTO `db...')
#3 C:\xampp\htdocs\DevOps\system\Database\BaseBuilder.php(2345): CodeIgniter\Database\BaseConnection->query('INSERT INTO `db...', Array, false)
#4 C:\xampp\htdocs\DevOps\system\Model.php(394): CodeIgniter\Database\BaseBuilder->insert()
#5 C:\xampp\htdocs\DevOps\system\BaseModel.php(839): CodeIgniter\Model->doInsert(Array)
#6 C:\xampp\htdocs\DevOps\system\Model.php(800): CodeIgniter\BaseModel->insert(Array, true)
#7 C:\xampp\htdocs\DevOps\tests\Models\UserModelTest.php(26): CodeIgniter\Model->insert(Array)
#8 C:\xampp\htdocs\DevOps\vendor\phpunit\phpunit\src\Framework\TestCase.php(1656): App\Tests\Models\UserModelTest->testInsertUser()
#9 C:\xampp\htdocs\DevOps\vendor\phpunit\phpunit\src\Framework\TestCase.php(514): PHPUnit\Framework\TestCase->runTest()
#10 C:\xampp\htdocs\DevOps\vendor\phpunit\phpunit\src\Framework\TestRunner\TestRunner.php(87): PHPUnit\Framework\TestCase->runBare()
#11 C:\xampp\htdocs\DevOps\vendor\phpunit\phpunit\src\Framework\TestCase.php(361): PHPUnit\Framework\TestRunner->run(Object(App\Tests\Models\UserModelTest))
#12 C:\xampp\htdocs\DevOps\vendor\phpunit\phpunit\src\Framework\TestSuite.php(369): PHPUnit\Framework\TestCase->run()
#13 C:\xampp\htdocs\DevOps\vendor\phpunit\phpunit\src\TextUI\TestRunner.php(64): PHPUnit\Framework\TestSuite->run()
#14 C:\xampp\htdocs\DevOps\vendor\phpunit\phpunit\src\TextUI\Application.php(210): PHPUnit\TextUI\TestRunner->run(Object(PHPUnit\TextUI\Configuration\Configuration), Object(PHPUnit\Runner\ResultCache\DefaultResultCache), Object(PHPUnit\Framework\TestSuite))
#15 C:\xampp\htdocs\DevOps\vendor\phpunit\phpunit\phpunit(104): PHPUnit\TextUI\Application->run(Array)
#16 C:\xampp\htdocs\DevOps\vendor\bin\phpunit(122): include('C:\\xampp\\htdocs...')
#17 {main}
ERROR - 2025-04-23 10:44:41 --> mysqli_sql_exception: Table 'devops_db.users' doesn't exist in C:\xampp\htdocs\DevOps\system\Database\MySQLi\Connection.php:327
Stack trace:
#0 C:\xampp\htdocs\DevOps\system\Database\MySQLi\Connection.php(327): mysqli->query('SELECT *\nFROM `...', 0)
#1 C:\xampp\htdocs\DevOps\system\Database\BaseConnection.php(738): CodeIgniter\Database\MySQLi\Connection->execute('SELECT *\nFROM `...')
#2 C:\xampp\htdocs\DevOps\system\Database\BaseConnection.php(652): CodeIgniter\Database\BaseConnection->simpleQuery('SELECT *\nFROM `...')
#3 C:\xampp\htdocs\DevOps\system\Database\BaseBuilder.php(1649): CodeIgniter\Database\BaseConnection->query('SELECT *\nFROM `...', Array, false)
#4 C:\xampp\htdocs\DevOps\system\Model.php(286): CodeIgniter\Database\BaseBuilder->get()
#5 C:\xampp\htdocs\DevOps\system\BaseModel.php(675): CodeIgniter\Model->doFindAll(0, 0)
#6 C:\xampp\htdocs\DevOps\tests\Models\UserModelTest.php(15): CodeIgniter\BaseModel->findAll()
#7 C:\xampp\htdocs\DevOps\vendor\phpunit\phpunit\src\Framework\TestCase.php(1656): App\Tests\Models\UserModelTest->testFindAllUsers()
#8 C:\xampp\htdocs\DevOps\vendor\phpunit\phpunit\src\Framework\TestCase.php(514): PHPUnit\Framework\TestCase->runTest()
#9 C:\xampp\htdocs\DevOps\vendor\phpunit\phpunit\src\Framework\TestRunner\TestRunner.php(87): PHPUnit\Framework\TestCase->runBare()
#10 C:\xampp\htdocs\DevOps\vendor\phpunit\phpunit\src\Framework\TestCase.php(361): PHPUnit\Framework\TestRunner->run(Object(App\Tests\Models\UserModelTest))
#11 C:\xampp\htdocs\DevOps\vendor\phpunit\phpunit\src\Framework\TestSuite.php(369): PHPUnit\Framework\TestCase->run()
#12 C:\xampp\htdocs\DevOps\vendor\phpunit\phpunit\src\TextUI\TestRunner.php(64): PHPUnit\Framework\TestSuite->run()
#13 C:\xampp\htdocs\DevOps\vendor\phpunit\phpunit\src\TextUI\Application.php(210): PHPUnit\TextUI\TestRunner->run(Object(PHPUnit\TextUI\Configuration\Configuration), Object(PHPUnit\Runner\ResultCache\DefaultResultCache), Object(PHPUnit\Framework\TestSuite))
#14 C:\xampp\htdocs\DevOps\vendor\phpunit\phpunit\phpunit(104): PHPUnit\TextUI\Application->run(Array)
#15 C:\xampp\htdocs\DevOps\vendor\bin\phpunit(122): include('C:\\xampp\\htdocs...')
#16 {main}
ERROR - 2025-04-23 10:44:42 --> mysqli_sql_exception: Table 'devops_db.users' doesn't exist in C:\xampp\htdocs\DevOps\system\Database\MySQLi\Connection.php:327
Stack trace:
#0 C:\xampp\htdocs\DevOps\system\Database\MySQLi\Connection.php(327): mysqli->query('INSERT INTO `us...', 0)
#1 C:\xampp\htdocs\DevOps\system\Database\BaseConnection.php(738): CodeIgniter\Database\MySQLi\Connection->execute('INSERT INTO `us...')
#2 C:\xampp\htdocs\DevOps\system\Database\BaseConnection.php(652): CodeIgniter\Database\BaseConnection->simpleQuery('INSERT INTO `us...')
#3 C:\xampp\htdocs\DevOps\system\Database\BaseBuilder.php(2345): CodeIgniter\Database\BaseConnection->query('INSERT INTO `us...', Array, false)
#4 C:\xampp\htdocs\DevOps\system\Model.php(394): CodeIgniter\Database\BaseBuilder->insert()
#5 C:\xampp\htdocs\DevOps\system\BaseModel.php(839): CodeIgniter\Model->doInsert(Array)
#6 C:\xampp\htdocs\DevOps\system\Model.php(800): CodeIgniter\BaseModel->insert(Array, true)
#7 C:\xampp\htdocs\DevOps\tests\Models\UserModelTest.php(26): CodeIgniter\Model->insert(Array)
#8 C:\xampp\htdocs\DevOps\vendor\phpunit\phpunit\src\Framework\TestCase.php(1656): App\Tests\Models\UserModelTest->testInsertUser()
#9 C:\xampp\htdocs\DevOps\vendor\phpunit\phpunit\src\Framework\TestCase.php(514): PHPUnit\Framework\TestCase->runTest()
#10 C:\xampp\htdocs\DevOps\vendor\phpunit\phpunit\src\Framework\TestRunner\TestRunner.php(87): PHPUnit\Framework\TestCase->runBare()
#11 C:\xampp\htdocs\DevOps\vendor\phpunit\phpunit\src\Framework\TestCase.php(361): PHPUnit\Framework\TestRunner->run(Object(App\Tests\Models\UserModelTest))
#12 C:\xampp\htdocs\DevOps\vendor\phpunit\phpunit\src\Framework\TestSuite.php(369): PHPUnit\Framework\TestCase->run()
#13 C:\xampp\htdocs\DevOps\vendor\phpunit\phpunit\src\TextUI\TestRunner.php(64): PHPUnit\Framework\TestSuite->run()
#14 C:\xampp\htdocs\DevOps\vendor\phpunit\phpunit\src\TextUI\Application.php(210): PHPUnit\TextUI\TestRunner->run(Object(PHPUnit\TextUI\Configuration\Configuration), Object(PHPUnit\Runner\ResultCache\DefaultResultCache), Object(PHPUnit\Framework\TestSuite))
#15 C:\xampp\htdocs\DevOps\vendor\phpunit\phpunit\phpunit(104): PHPUnit\TextUI\Application->run(Array)
#16 C:\xampp\htdocs\DevOps\vendor\bin\phpunit(122): include('C:\\xampp\\htdocs...')
#17 {main}
ERROR - 2025-04-23 10:52:32 --> mysqli_sql_exception: Unknown column 'name' in 'field list' in C:\xampp\htdocs\DevOps\system\Database\MySQLi\Connection.php:327
Stack trace:
#0 C:\xampp\htdocs\DevOps\system\Database\MySQLi\Connection.php(327): mysqli->query('INSERT INTO `db...', 0)
#1 C:\xampp\htdocs\DevOps\system\Database\BaseConnection.php(738): CodeIgniter\Database\MySQLi\Connection->execute('INSERT INTO `db...')
#2 C:\xampp\htdocs\DevOps\system\Database\BaseConnection.php(652): CodeIgniter\Database\BaseConnection->simpleQuery('INSERT INTO `db...')
#3 C:\xampp\htdocs\DevOps\system\Database\BaseBuilder.php(2345): CodeIgniter\Database\BaseConnection->query('INSERT INTO `db...', Array, false)
#4 C:\xampp\htdocs\DevOps\system\Model.php(394): CodeIgniter\Database\BaseBuilder->insert()
#5 C:\xampp\htdocs\DevOps\system\BaseModel.php(839): CodeIgniter\Model->doInsert(Array)
#6 C:\xampp\htdocs\DevOps\system\Model.php(800): CodeIgniter\BaseModel->insert(Array, true)
#7 C:\xampp\htdocs\DevOps\tests\Models\UserModelTest.php(26): CodeIgniter\Model->insert(Array)
#8 C:\xampp\htdocs\DevOps\vendor\phpunit\phpunit\src\Framework\TestCase.php(1656): App\Tests\Models\UserModelTest->testInsertUser()
#9 C:\xampp\htdocs\DevOps\vendor\phpunit\phpunit\src\Framework\TestCase.php(514): PHPUnit\Framework\TestCase->runTest()
#10 C:\xampp\htdocs\DevOps\vendor\phpunit\phpunit\src\Framework\TestRunner\TestRunner.php(87): PHPUnit\Framework\TestCase->runBare()
#11 C:\xampp\htdocs\DevOps\vendor\phpunit\phpunit\src\Framework\TestCase.php(361): PHPUnit\Framework\TestRunner->run(Object(App\Tests\Models\UserModelTest))
#12 C:\xampp\htdocs\DevOps\vendor\phpunit\phpunit\src\Framework\TestSuite.php(369): PHPUnit\Framework\TestCase->run()
#13 C:\xampp\htdocs\DevOps\vendor\phpunit\phpunit\src\TextUI\TestRunner.php(64): PHPUnit\Framework\TestSuite->run()
#14 C:\xampp\htdocs\DevOps\vendor\phpunit\phpunit\src\TextUI\Application.php(210): PHPUnit\TextUI\TestRunner->run(Object(PHPUnit\TextUI\Configuration\Configuration), Object(PHPUnit\Runner\ResultCache\DefaultResultCache), Object(PHPUnit\Framework\TestSuite))
#15 C:\xampp\htdocs\DevOps\vendor\phpunit\phpunit\phpunit(104): PHPUnit\TextUI\Application->run(Array)
#16 C:\xampp\htdocs\DevOps\vendor\bin\phpunit(122): include('C:\\xampp\\htdocs...')
#17 {main}
ERROR - 2025-04-23 09:38:19 --> mysqli_sql_exception: Duplicate entry '0' for key 'panier.PRIMARY' in C:\xampp\htdocs\DevOps\system\Database\MySQLi\Connection.php:327
Stack trace:
#0 C:\xampp\htdocs\DevOps\system\Database\MySQLi\Connection.php(327): mysqli->query('INSERT INTO `pa...', 0)
#1 C:\xampp\htdocs\DevOps\system\Database\BaseConnection.php(738): CodeIgniter\Database\MySQLi\Connection->execute('INSERT INTO `pa...')
#2 C:\xampp\htdocs\DevOps\system\Database\BaseConnection.php(652): CodeIgniter\Database\BaseConnection->simpleQuery('INSERT INTO `pa...')
#3 C:\xampp\htdocs\DevOps\system\Database\BaseBuilder.php(2345): CodeIgniter\Database\BaseConnection->query('INSERT INTO `pa...', Array, false)
#4 C:\xampp\htdocs\DevOps\system\Model.php(394): CodeIgniter\Database\BaseBuilder->insert()
#5 C:\xampp\htdocs\DevOps\system\BaseModel.php(839): CodeIgniter\Model->doInsert(Array)
#6 C:\xampp\htdocs\DevOps\system\Model.php(800): CodeIgniter\BaseModel->insert(Array, true)
#7 C:\xampp\htdocs\DevOps\tests\Models\PanierModelTest.php(34): CodeIgniter\Model->insert(Array)
#8 C:\xampp\htdocs\DevOps\vendor\phpunit\phpunit\src\Framework\TestCase.php(1656): App\Tests\Models\PanierModelTest->testFindAllPanier()
#9 C:\xampp\htdocs\DevOps\vendor\phpunit\phpunit\src\Framework\TestCase.php(514): PHPUnit\Framework\TestCase->runTest()
#10 C:\xampp\htdocs\DevOps\vendor\phpunit\phpunit\src\Framework\TestRunner\TestRunner.php(87): PHPUnit\Framework\TestCase->runBare()
#11 C:\xampp\htdocs\DevOps\vendor\phpunit\phpunit\src\Framework\TestCase.php(361): PHPUnit\Framework\TestRunner->run(Object(App\Tests\Models\PanierModelTest))
#12 C:\xampp\htdocs\DevOps\vendor\phpunit\phpunit\src\Framework\TestSuite.php(369): PHPUnit\Framework\TestCase->run()
#13 C:\xampp\htdocs\DevOps\vendor\phpunit\phpunit\src\TextUI\TestRunner.php(64): PHPUnit\Framework\TestSuite->run()
#14 C:\xampp\htdocs\DevOps\vendor\phpunit\phpunit\src\TextUI\Application.php(210): PHPUnit\TextUI\TestRunner->run(Object(PHPUnit\TextUI\Configuration\Configuration), Object(PHPUnit\Runner\ResultCache\DefaultResultCache), Object(PHPUnit\Framework\TestSuite))
#15 C:\xampp\htdocs\DevOps\vendor\phpunit\phpunit\phpunit(104): PHPUnit\TextUI\Application->run(Array)
#16 C:\xampp\htdocs\DevOps\vendor\bin\phpunit(122): include('C:\\xampp\\htdocs...')
#17 {main}
ERROR - 2025-04-23 22:19:03 --> mysqli_sql_exception: Duplicate entry '0' for key 'panier.PRIMARY' in C:\xampp\htdocs\DevOps\system\Database\MySQLi\Connection.php:327
Stack trace:
#0 C:\xampp\htdocs\DevOps\system\Database\MySQLi\Connection.php(327): mysqli->query('INSERT INTO `pa...', 0)
#1 C:\xampp\htdocs\DevOps\system\Database\BaseConnection.php(738): CodeIgniter\Database\MySQLi\Connection->execute('INSERT INTO `pa...')
#2 C:\xampp\htdocs\DevOps\system\Database\BaseConnection.php(652): CodeIgniter\Database\BaseConnection->simpleQuery('INSERT INTO `pa...')
#3 C:\xampp\htdocs\DevOps\system\Database\BaseBuilder.php(2345): CodeIgniter\Database\BaseConnection->query('INSERT INTO `pa...', Array, false)
#4 C:\xampp\htdocs\DevOps\system\Model.php(394): CodeIgniter\Database\BaseBuilder->insert()
#5 C:\xampp\htdocs\DevOps\system\BaseModel.php(839): CodeIgniter\Model->doInsert(Array)
#6 C:\xampp\htdocs\DevOps\system\Model.php(800): CodeIgniter\BaseModel->insert(Array, true)
#7 C:\xampp\htdocs\DevOps\tests\Models\PanierModelTest.php(21): CodeIgniter\Model->insert(Array)
#8 C:\xampp\htdocs\DevOps\vendor\phpunit\phpunit\src\Framework\TestCase.php(1656): App\Tests\Models\PanierModelTest->testInsertPanier()
#9 C:\xampp\htdocs\DevOps\vendor\phpunit\phpunit\src\Framework\TestCase.php(514): PHPUnit\Framework\TestCase->runTest()
#10 C:\xampp\htdocs\DevOps\vendor\phpunit\phpunit\src\Framework\TestRunner\TestRunner.php(87): PHPUnit\Framework\TestCase->runBare()
#11 C:\xampp\htdocs\DevOps\vendor\phpunit\phpunit\src\Framework\TestCase.php(361): PHPUnit\Framework\TestRunner->run(Object(App\Tests\Models\PanierModelTest))
#12 C:\xampp\htdocs\DevOps\vendor\phpunit\phpunit\src\Framework\TestSuite.php(369): PHPUnit\Framework\TestCase->run()
#13 C:\xampp\htdocs\DevOps\vendor\phpunit\phpunit\src\TextUI\TestRunner.php(64): PHPUnit\Framework\TestSuite->run()
#14 C:\xampp\htdocs\DevOps\vendor\phpunit\phpunit\src\TextUI\Application.php(210): PHPUnit\TextUI\TestRunner->run(Object(PHPUnit\TextUI\Configuration\Configuration), Object(PHPUnit\Runner\ResultCache\DefaultResultCache), Object(PHPUnit\Framework\TestSuite))
#15 C:\xampp\htdocs\DevOps\vendor\phpunit\phpunit\phpunit(104): PHPUnit\TextUI\Application->run(Array)
#16 C:\xampp\htdocs\DevOps\vendor\bin\phpunit(122): include('C:\\xampp\\htdocs...')
#17 {main}
ERROR - 2025-04-23 22:19:03 --> mysqli_sql_exception: Duplicate entry '0' for key 'panier.PRIMARY' in C:\xampp\htdocs\DevOps\system\Database\MySQLi\Connection.php:327
Stack trace:
#0 C:\xampp\htdocs\DevOps\system\Database\MySQLi\Connection.php(327): mysqli->query('INSERT INTO `pa...', 0)
#1 C:\xampp\htdocs\DevOps\system\Database\BaseConnection.php(738): CodeIgniter\Database\MySQLi\Connection->execute('INSERT INTO `pa...')
#2 C:\xampp\htdocs\DevOps\system\Database\BaseConnection.php(652): CodeIgniter\Database\BaseConnection->simpleQuery('INSERT INTO `pa...')
#3 C:\xampp\htdocs\DevOps\system\Database\BaseBuilder.php(2345): CodeIgniter\Database\BaseConnection->query('INSERT INTO `pa...', Array, false)
#4 C:\xampp\htdocs\DevOps\system\Model.php(394): CodeIgniter\Database\BaseBuilder->insert()
#5 C:\xampp\htdocs\DevOps\system\BaseModel.php(839): CodeIgniter\Model->doInsert(Array)
#6 C:\xampp\htdocs\DevOps\system\Model.php(800): CodeIgniter\BaseModel->insert(Array, true)
#7 C:\xampp\htdocs\DevOps\tests\Models\PanierModelTest.php(34): CodeIgniter\Model->insert(Array)
#8 C:\xampp\htdocs\DevOps\vendor\phpunit\phpunit\src\Framework\TestCase.php(1656): App\Tests\Models\PanierModelTest->testFindAllPanier()
#9 C:\xampp\htdocs\DevOps\vendor\phpunit\phpunit\src\Framework\TestCase.php(514): PHPUnit\Framework\TestCase->runTest()
#10 C:\xampp\htdocs\DevOps\vendor\phpunit\phpunit\src\Framework\TestRunner\TestRunner.php(87): PHPUnit\Framework\TestCase->runBare()
#11 C:\xampp\htdocs\DevOps\vendor\phpunit\phpunit\src\Framework\TestCase.php(361): PHPUnit\Framework\TestRunner->run(Object(App\Tests\Models\PanierModelTest))
#12 C:\xampp\htdocs\DevOps\vendor\phpunit\phpunit\src\Framework\TestSuite.php(369): PHPUnit\Framework\TestCase->run()
#13 C:\xampp\htdocs\DevOps\vendor\phpunit\phpunit\src\TextUI\TestRunner.php(64): PHPUnit\Framework\TestSuite->run()
#14 C:\xampp\htdocs\DevOps\vendor\phpunit\phpunit\src\TextUI\Application.php(210): PHPUnit\TextUI\TestRunner->run(Object(PHPUnit\TextUI\Configuration\Configuration), Object(PHPUnit\Runner\ResultCache\DefaultResultCache), Object(PHPUnit\Framework\TestSuite))
#15 C:\xampp\htdocs\DevOps\vendor\phpunit\phpunit\phpunit(104): PHPUnit\TextUI\Application->run(Array)
#16 C:\xampp\htdocs\DevOps\vendor\bin\phpunit(122): include('C:\\xampp\\htdocs...')
#17 {main}
